<mujoco model="ur5e">
  <compiler angle="radian" />

  <option integrator="implicitfast" />

  <default>
    <default class="ur5e">
      <material specular="0.5" shininess="0.25" />
      <joint axis="0 1 0" range="-3.1415 3.1415" limited="false" armature="0.1" damping="0.1" />
      <general gaintype="fixed" biastype="affine" ctrlrange="-3.1415 3.1415" gainprm="4000"
        biasprm="0 -4000 -400" forcerange="-150 150" forcelimited="true" />
      <default class="size3">
        <default class="size3_limited">
          <joint range="-3.1415 3.1415" />
          <general ctrlrange="-3.1415 3.1415" />
        </default>
      </default>
      <default class="size1">
        <general gainprm="500" biasprm="0 -500 -100" forcerange="-28 28" forcelimited="true" />
      </default>
      <default class="ur5e_visual">
        <geom type="mesh" contype="0" conaffinity="0" group="2" />
      </default>
      <default class="ur5e_collision">
        <geom type="capsule" group="3" />
        <default class="eef_collision">
          <geom type="cylinder" />
        </default>
      </default>
      <site size="0.001" rgba="0.5 0.5 0.5 0.3" group="4" />

      <!-- <default class="weightless_arm">
        <body gravcomp="1" />
      </default> -->
    </default>

    <default class="2f85">
      <mesh scale="0.001 0.001 0.001" />
      <general biastype="affine" />

      <joint axis="0 0 1" />
      <default class="driver">
        <joint range="0 0.9" armature="0.005" damping="0.1" solimplimit="0.95 0.99 0.001"
          solreflimit="0.005 1" />
      </default>
      <default class="follower">
        <joint range="-0.872664 0.9" armature="0.001" solimplimit="0.95 0.99 0.001"
          solreflimit="0.005 1" />
      </default>
      <default class="spring_link">
        <joint range="-0.29670597283 0.9" armature="0.001" stiffness="0.05" springref="2.62"
          damping="0.00125" />
      </default>
      <default class="coupler">
        <joint range="-1.57 0" armature="0.001" solimplimit="0.95 0.99 0.001" solreflimit="0.005 1" />
      </default>

      <default class="2f85_visual">
        <geom type="mesh" contype="0" conaffinity="0" group="2" material="black" />
      </default>

      <default class="2f85_collision">
        <geom type="mesh" group="3" />
        <default class="pad_box1">
          <geom mass="1e-6" type="box" pos="0.043258  0 0.12" size="0.002 0.011 0.009375"
            friction="2.0 0.1 0.001"
            solimp="0.95 0.99 0.001" solref="0.004 1" priority="1" rgba="0.55 0.55 0.55 1" />
        </default>
        <default class="pad_box2">
          <geom mass="1e-6" type="box" pos="0.043258 0 0.13875" size="0.002 0.011 0.009375"
            friction="2.0 0.1 0.001"
            solimp="0.95 0.99 0.001" solref="0.004 1" priority="1" rgba="0.45 0.45 0.45 1" />
        </default>
      </default>

      <default class="gopro_visual">
        <geom type="mesh" contype="0" conaffinity="0" density="0" group="2" />
      </default>
      <default class="gopro_collision">
        <geom type="mesh" group="3" />
      </default>

    </default>
  </default>

  <asset>
    <material class="ur5e" name="black" rgba="0.033 0.033 0.033 1" />
    <material class="ur5e" name="jointgray" rgba="0.278 0.278 0.278 1" />
    <material class="ur5e" name="linkgray" rgba="0.82 0.82 0.82 1" />
    <material class="ur5e" name="urblue" rgba="0.49 0.678 0.8 1" />

    <mesh file="ur5e/assets/base_0.obj" />
    <mesh file="ur5e/assets/base_1.obj" />
    <mesh file="ur5e/assets/shoulder_0.obj" />
    <mesh file="ur5e/assets/shoulder_1.obj" />
    <mesh file="ur5e/assets/shoulder_2.obj" />
    <mesh file="ur5e/assets/upperarm_0.obj" />
    <mesh file="ur5e/assets/upperarm_1.obj" />
    <mesh file="ur5e/assets/upperarm_2.obj" />
    <mesh file="ur5e/assets/upperarm_3.obj" />
    <mesh file="ur5e/assets/forearm_0.obj" />
    <mesh file="ur5e/assets/forearm_1.obj" />
    <mesh file="ur5e/assets/forearm_2.obj" />
    <mesh file="ur5e/assets/forearm_3.obj" />
    <mesh file="ur5e/assets/wrist1_0.obj" />
    <mesh file="ur5e/assets/wrist1_1.obj" />
    <mesh file="ur5e/assets/wrist1_2.obj" />
    <mesh file="ur5e/assets/wrist2_0.obj" />
    <mesh file="ur5e/assets/wrist2_1.obj" />
    <mesh file="ur5e/assets/wrist2_2.obj" />
    <mesh file="ur5e/assets/wrist3.obj" />

    <material name="metal" rgba="0.58 0.58 0.58 1" />
    <material name="silicone" rgba="0.1882 0.1882 0.1882 1" />
    <material name="gray" rgba="0.15 0.15 0.15 1" />
    <!-- <material name="black" rgba="0.149 0.149 0.149 1" /> -->

    <mesh file="robotiq_2f85_v4/assets/base.stl" />
    <mesh file="robotiq_2f85_v4/assets/base_coupling.stl" />
    <mesh file="robotiq_2f85_v4/assets/c-a01-85-open.stl" />
    <mesh file="robotiq_2f85_v4/assets/driver.stl" />
    <mesh file="robotiq_2f85_v4/assets/coupler.stl" />
    <mesh file="robotiq_2f85_v4/assets/spring_link.stl" />
    <mesh file="robotiq_2f85_v4/assets/follower.stl" />
    <mesh file="robotiq_2f85_v4/assets/tongue.stl" />


    <mesh file="umi_gripper/assets/gopro.stl" />


  </asset>

  <worldbody>
    <light name="spotlight" mode="targetbodycom" target="wrist_2_link" pos="0 -1 2" specular="0 0 0"
      castshadow="false" />

    <body name="base" pos="0 0 0" euler="0 0 0" childclass="ur5e" gravcomp="1">
      <inertial mass="4.0" pos="0 0 0" diaginertia="0.00443333156 0.00443333156 0.0072" />
      <geom mesh="base_0" material="black" class="ur5e_visual" />
      <geom mesh="base_1" material="jointgray" class="ur5e_visual" />
      <body name="shoulder_link" pos="0 0 0.163" gravcomp="1">
        <inertial mass="3.7" pos="0 0 0" diaginertia="0.0102675 0.0102675 0.00666" />
        <joint name="shoulder_pan_joint" class="size3" axis="0 0 1" />
        <geom mesh="shoulder_0" material="urblue" class="ur5e_visual" />
        <geom mesh="shoulder_1" material="black" class="ur5e_visual" />
        <geom mesh="shoulder_2" material="jointgray" class="ur5e_visual" />
        <geom class="ur5e_collision" size="0.06 0.06" pos="0 0 -0.04" />
        <body name="upper_arm_link" pos="0 0.138 0" quat="1 0 1 0" gravcomp="1">
          <inertial mass="8.393" pos="0 0 0.2125" diaginertia="0.133886 0.133886 0.0151074" />
          <joint name="shoulder_lift_joint" class="size3" />
          <geom mesh="upperarm_0" material="linkgray" class="ur5e_visual" />
          <geom mesh="upperarm_1" material="black" class="ur5e_visual" />
          <geom mesh="upperarm_2" material="jointgray" class="ur5e_visual" />
          <geom mesh="upperarm_3" material="urblue" class="ur5e_visual" />
          <geom class="ur5e_collision" pos="0 -0.04 0" quat="1 1 0 0" size="0.06 0.06" />
          <geom class="ur5e_collision" size="0.05 0.2" pos="0 0 0.2" />
          <body name="forearm_link" pos="0 -0.131 0.425" gravcomp="1">
            <inertial mass="2.275" pos="0 0 0.196" diaginertia="0.0311796 0.0311796 0.004095" />
            <joint name="elbow_joint" class="size3_limited" />
            <geom mesh="forearm_0" material="urblue" class="ur5e_visual" />
            <geom mesh="forearm_1" material="linkgray" class="ur5e_visual" />
            <geom mesh="forearm_2" material="black" class="ur5e_visual" />
            <geom mesh="forearm_3" material="jointgray" class="ur5e_visual" />
            <geom class="ur5e_collision" pos="0 0.08 0" quat="1 1 0 0" size="0.055 0.06" />
            <geom class="ur5e_collision" size="0.038 0.19" pos="0 0 0.2" />
            <body name="wrist_1_link" pos="0 0 0.392" quat="1 0 1 0" gravcomp="1">
              <inertial mass="1.219" pos="0 0.127 0" diaginertia="0.0025599 0.0025599 0.0021942" />
              <joint name="wrist_1_joint" class="size1" />
              <geom mesh="wrist1_0" material="black" class="ur5e_visual" />
              <geom mesh="wrist1_1" material="urblue" class="ur5e_visual" />
              <geom mesh="wrist1_2" material="jointgray" class="ur5e_visual" />
              <geom class="ur5e_collision" pos="0 0.05 0" quat="1 1 0 0" size="0.04 0.07" />
              <body name="wrist_2_link" pos="0 0.127 0" gravcomp="1">
                <inertial mass="1.219" pos="0 0 0.1" diaginertia="0.0025599 0.0025599 0.0021942" />
                <joint name="wrist_2_joint" axis="0 0 1" class="size1" />
                <geom mesh="wrist2_0" material="black" class="ur5e_visual" />
                <geom mesh="wrist2_1" material="urblue" class="ur5e_visual" />
                <geom mesh="wrist2_2" material="jointgray" class="ur5e_visual" />
                <geom class="ur5e_collision" size="0.04 0.06" pos="0 0 0.04" />
                <geom class="ur5e_collision" pos="0 0.02 0.1" quat="1 1 0 0" size="0.04 0.04" />
                <body name="wrist_3_link" pos="0 0 0.1" gravcomp="1">
                  <inertial mass="0.1889" pos="0 0.0771683 0" quat="1 0 0 1"
                    diaginertia="0.000132134 9.90863e-05 9.90863e-05" />
                  <joint name="wrist_3_joint" class="size1" />
                  <geom material="linkgray" mesh="wrist3" class="ur5e_visual" />
                  <geom class="eef_collision" pos="0 0.08 0" quat="1 1 0 0" size="0.04 0.02" />
                  <site name="attachment_site" pos="0 0.1 0" quat="-1 1 0 0" />
                  <site name="gripper_center" pos="0 0.25 0" />

                  <!-- GoPro Camera -->
                  <geom pos="0.0 0.1 0.05" xyaxes="1 0 0 0 0 1" type="box"
                    size="0.035 0.025 0.015"
                    material="gray" contype="0" conaffinity="0" />
                  <!-- <geom pos="0.0 0.15 0.05" quat="0.5 0.5 -0.5 -0.5" mesh="gopro"
                    class="gopro_collision" /> -->

                  <camera name="wrist_camera" pos="0.0 0.125 0.05" xyaxes="1 0 0 0 0 1"
                    mode="fixed"
                    fovy="60" />


                  <body name="2f85_base" pos="0 0.1 0" quat="-1 1 0 0" childclass="2f85">
                    <inertial mass="0.777441" pos="7.77116e-05 8.42713e-05 0.0311656"
                      quat="0.704758 -0.00373684 -0.00570287 0.709415"
                      diaginertia="0.000260285 0.000225381 0.000152708" />
                    <geom class="2f85_visual" pos="0 0 0.0108" quat="0 0 0 1" mesh="base" />
                    <geom class="2f85_visual" pos="0 0 0.004" quat="1 -1 0 0" mesh="base_coupling" />
                    <geom class="2f85_visual" pos="0 0 0.0108" quat="1 0 0 0" material="metal"
                      mesh="c-a01-85-open" />
                    <geom class="2f85_collision" mesh="base" />
                    <!-- Left-hand side 4-bar linkage -->
                    <body name="left_driver" pos="-0.0306011 0.00475 0.0657045" quat="1 -1 0 0">
                      <inertial mass="0.00899563" pos="-0.0175297 0.00165308 -0.00469625"
                        quat="-0.469642 0.469642 -0.528617 0.528617"
                        diaginertia="1.72352e-06 1.60906e-06 3.22006e-07" />
                      <joint name="left_driver_joint" class="driver" />
                      <geom class="2f85_visual" pos="0.0306011 0.0549045 -0.0047" quat="1 1 0 0"
                        material="metal" mesh="driver" />
                      <geom class="2f85_collision" pos="0.0306011 0.0549045 -0.0047" quat="1 1 0 0"
                        mesh="driver" />
                      <body name="left_coupler" pos="-0.0314249 0.00453223 -0.0102" quat="0 0 0 1">
                        <inertial mass="0.0140974" pos="0.00367747 0.01986 0.0055"
                          quat="0.701447 -0.701447 0.0892884 -0.0892884"
                          diaginertia="4.16206e-06 3.52216e-06 8.88131e-07" />
                        <geom class="2f85_visual" pos="-0.062026 -0.0503723 0.0055" quat="1 -1 0 0"
                          mesh="coupler" />
                        <geom class="2f85_collision" pos="-0.062026 -0.0503723 0.0055"
                          quat="1 -1 0 0"
                          mesh="coupler" />
                      </body>
                    </body>
                    <body name="left_spring_link" pos="-0.0127 -0.012 0.07222" quat="1 -1 0 0">
                      <inertial mass="0.0221642" pos="-0.0183 -0.0205732 0.01205"
                        quat="0.660941 0.660941 -0.251309 -0.251309"
                        diaginertia="8.96853e-06 6.71733e-06 2.63931e-06" />
                      <joint name="left_spring_link_joint" class="spring_link" />
                      <geom class="2f85_visual" pos="0.0127 0.06142 0.01205" quat="1 1 0 0"
                        type="mesh"
                        mesh="spring_link" />
                      <geom class="2f85_collision" pos="0.0127 0.06142 0.01205" quat="1 1 0 0"
                        type="mesh" mesh="spring_link" />
                      <body name="left_follower" pos="-0.0382079 -0.0425003 0.00295"
                        quat="0 -1 -1.90231e-05 0">
                        <inertial mass="0.0125222" pos="-0.00852976 -0.0014822 -0.00910001"
                          quat="0.359439 0.359439 0.608937 0.608937"
                          diaginertia="2.67415e-06 2.4559e-06 6.02031e-07" />
                        <joint name="left_follower" class="follower" />
                        <geom class="2f85_visual" pos="0.0509079 -0.10392 -0.0091" quat="1 -1 0 0"
                          type="mesh" mesh="follower" />
                        <geom class="2f85_visual" pos="0.0509079 -0.10392 -0.0091" quat="1 -1 0 0"
                          type="mesh" material="metal" mesh="tongue" />
                        <geom class="2f85_collision" pos="0.0509079 -0.10392 -0.0091"
                          quat="1 -1 0 0"
                          type="mesh" mesh="follower" />
                        <geom class="2f85_collision" pos="0.0509079 -0.10392 -0.0091"
                          quat="1 -1 0 0"
                          type="mesh" mesh="tongue" />
                        <body name="left_pad" pos="-0.0377897 -0.103916 -0.0091" quat="1 -1 0 0">
                          <geom class="pad_box1" name="left_pad1" />
                          <geom class="pad_box2" name="left_pad2" />
                        </body>
                      </body>
                    </body>
                    <!-- Right-hand side 4-bar linkage -->
                    <body name="right_driver" pos="0.0306011 -0.00475 0.0657045" quat="0 0 -1 1">
                      <inertial mass="0.00899563" pos="-0.0175297 0.00165308 -0.00469625"
                        quat="-0.469642 0.469642 -0.528617 0.528617"
                        diaginertia="1.72352e-06 1.60906e-06 3.22006e-07" />
                      <joint name="right_driver_joint" class="driver" />
                      <geom class="2f85_visual" pos="0.0306011 0.0549045 -0.0047" quat="1 1 0 0"
                        material="metal" mesh="driver" />
                      <geom class="2f85_collision" pos="0.0306011 0.0549045 -0.0047" quat="1 1 0 0"
                        mesh="driver" />
                      <body name="right_coupler" pos="-0.0314249 0.00453223 -0.0102" quat="0 0 0 1">
                        <inertial mass="0.0140974" pos="0.00367747 0.01986 0.0055"
                          quat="0.701447 -0.701447 0.0892884 -0.0892884"
                          diaginertia="4.16206e-06 3.52216e-06 8.88131e-07" />
                        <geom class="2f85_visual" pos="-0.062026 -0.0503723 0.0055" quat="1 -1 0 0"
                          mesh="coupler" />
                        <geom class="2f85_collision" pos="-0.062026 -0.0503723 0.0055"
                          quat="1 -1 0 0"
                          mesh="coupler" />
                      </body>
                    </body>
                    <body name="right_spring_link" pos="0.0127 0.012 0.07222" quat="0 0 -1 1">
                      <inertial mass="0.0221642" pos="-0.0183 -0.0205732 0.01205"
                        quat="0.660941 0.660941 -0.251309 -0.251309"
                        diaginertia="8.96853e-06 6.71733e-06 2.63931e-06" />
                      <joint name="right_spring_link_joint" class="spring_link" />
                      <geom class="2f85_visual" pos="0.0127 0.06142 0.01205" quat="1 1 0 0"
                        mesh="spring_link" />
                      <geom class="2f85_collision" pos="0.0127 0.06142 0.01205" quat="1 1 0 0"
                        mesh="spring_link" />
                      <body name="right_follower" pos="-0.0382079 -0.0425003 0.00295"
                        quat="0 -1 0 0">
                        <inertial mass="0.0125222" pos="-0.00852976 -0.0014822 -0.00910001"
                          quat="0.359439 0.359439 0.608937 0.608937"
                          diaginertia="2.67415e-06 2.4559e-06 6.02031e-07" />
                        <joint name="right_follower_joint" class="follower" />
                        <geom class="2f85_visual" pos="0.0509079 -0.10392 -0.0091" quat="1 -1 0 0"
                          material="metal" mesh="tongue" />
                        <geom class="2f85_visual" pos="0.0509079 -0.10392 -0.0091" quat="1 -1 0 0"
                          mesh="follower" />
                        <geom class="2f85_collision" pos="0.0509079 -0.10392 -0.0091"
                          quat="1 -1 0 0"
                          mesh="tongue" />
                        <geom class="2f85_collision" pos="0.0509079 -0.10392 -0.0091"
                          quat="1 -1 0 0"
                          mesh="follower" />
                        <body name="right_pad" pos="-0.0377897 -0.103916 -0.0091" quat="1 -1 0 0">
                          <geom class="pad_box1" name="right_pad1" />
                          <geom class="pad_box2" name="right_pad2" />
                        </body>
                      </body>
                    </body>
                  </body>


                </body>
              </body>
            </body>
          </body>
        </body>
      </body>
    </body>
  </worldbody>

  <contact>
    <exclude body1="2f85_base" body2="left_driver" />
    <exclude body1="2f85_base" body2="right_driver" />
    <exclude body1="2f85_base" body2="left_spring_link" />
    <exclude body1="2f85_base" body2="right_spring_link" />
    <exclude body1="right_coupler" body2="right_follower" />
    <exclude body1="left_coupler" body2="left_follower" />
  </contact>

  <!--
    This adds stability to the model by having a tendon that distributes the forces between both
    joints, such that the equality constraint doesn't have to do that much work in order to equalize
    both joints. Since both joints share the same sign, we split the force between both equally by
    setting coef=0.485
  -->
  <tendon>
    <fixed name="split">
      <joint joint="right_driver_joint" coef="0.485" />
      <joint joint="left_driver_joint" coef="0.485" />
    </fixed>
  </tendon>

  <equality>
    <connect anchor="-0.0179014 -0.00651468 0.0044" body1="right_follower" body2="right_coupler"
      solimp="0.95 0.99 0.001" solref="0.005 1" />
    <connect anchor="-0.0179014 -0.00651468 0.0044" body1="left_follower" body2="left_coupler"
      solimp="0.95 0.99 0.001" solref="0.005 1" />
    <joint joint1="right_driver_joint" joint2="left_driver_joint" polycoef="0 1 0 0 0"
      solimp="0.95 0.99 0.001"
      solref="0.005 1" />
  </equality>

  <actuator>
    <general class="size3" name="shoulder_pan" joint="shoulder_pan_joint" />
    <general class="size3" name="shoulder_lift" joint="shoulder_lift_joint" />
    <general class="size3_limited" name="elbow" joint="elbow_joint" />
    <general class="size1" name="wrist_1" joint="wrist_1_joint" />
    <general class="size1" name="wrist_2" joint="wrist_2_joint" />
    <general class="size1" name="wrist_3" joint="wrist_3_joint" />

    <general class="2f85" name="fingers_actuator" tendon="split" forcerange="-5 5"
      ctrlrange="0
    255"
      gainprm="0.3137255 0 0" biasprm="0 -100 -10" />
  </actuator>

  <keyframe>
    <!-- <key name="home" qpos="-1.5708 -1.5708 1.5708 -1.5708 -1.5708 0" /> -->
    <key name="home1" qpos="0.7 -0.0 -2.43 -1.2 1.5708 3.1415" />
    <!--
    ctrl="-1.5708 -1.5708
    1.5708 -1.5708 -1.5708 0" /> -->
  </keyframe>
</mujoco>